Workbook

Sheet Back-End Page
A1: Year | B1: MONTHLY OVERVIEW TOTAL | G1: =UPPER(TEXT('Setup Page'!$AC18,"mmm yy")) -> JUL 23 | H1: =UPPER(TEXT('Setup Page'!$AC19,"mmm yy")) -> AUG 23 | I1: =UPPER(TEXT('Setup Page'!$AC20,"mmm yy")) -> SEP 23 | J1: =UPPER(TEXT('Setup Page'!$AC21,"mmm yy")) -> OCT 23 | K1: =UPPER(TEXT('Setup Page'!$AC22,"mmm yy")) -> NOV 23 | L1: =UPPER(TEXT('Setup Page'!$AC23,"mmm yy")) -> DEC 23 | M1: =UPPER(TEXT('Setup Page'!$AC24,"mmm yy")) -> JAN 24 | N1: =UPPER(TEXT('Setup Page'!$AC25,"mmm yy")) -> FEB 24 | O1: =UPPER(TEXT('Setup Page'!$AC26,"mmm yy")) -> MAR 24 | P1: =UPPER(TEXT('Setup Page'!$AC27,"mmm yy")) -> APR 24 | Q1: =UPPER(TEXT('Setup Page'!$AC28,"mmm yy")) -> MAY 24 | R1: =UPPER(TEXT('Setup Page'!$AC29,"mmm yy")) -> JUN 24
A2: 1960 | B2: INCOME CATEGORIES | C2: TOTAL AMOUNT | D2: NET | E2: TAX | F2: M O N T H L Y P R O F I T | G2: =Annual!M113 -> 4987.04 | H2: =Annual!R113 -> 6535.6 | I2: =Annual!W113 -> 4980 | J2: =Annual!AB113 -> 8471.2 | K2: =Annual!AG113 -> 6890.2 | L2: =Annual!AL113 -> 2510.27 | M2: =Annual!AQ113 -> 12713.25 | N2: =Annual!AV113 -> 12196.61 | O2: =Annual!BA113 -> 20276.84 | P2: =Annual!BF113 -> 12970.2 | Q2: =Annual!BK113 -> 8771.2 | R2: =Annual!BP113 -> 5870.2
A3: 1961 | B3: ='Setup Page'!C18 -> Investment | C3: =SUMIFS('Income Entry'!$F$11:$F1000,'Income Entry'!$L$11:$L1000,B3,'Income Entry'!$S$11:$S1000,Monthly!$K$10,'Income Entry'!$T$11:$T1000,Monthly!$S$10) -> 0 | D3: =SUMIFS('Income Entry'!$H$11:$H1000,'Income Entry'!$L$11:$L1000,B3,'Income Entry'!$S$11:$S1000,Monthly!$K$10,'Income Entry'!$T$11:$T1000,Monthly!$S$10) -> 0 | E3: =SUMIFS('Income Entry'!$I$11:$I1000,'Income Entry'!$L$11:$L1000,B3,'Income Entry'!$S$11:$S1000,Monthly!$K$10,'Income Entry'!$T$11:$T1000,Monthly!$S$10) -> 0 | F3: M O N T H L Y P R O F I T G O A L | G3: =Annual!M114 -> 0 | H3: =Annual!R114 -> 0 | I3: =Annual!W114 -> 2400 | J3: =Annual!AB114 -> 2400 | K3: =Annual!AG114 -> 2400 | L3: =Annual!AL114 -> 6000 | M3: =Annual!AQ114 -> 6000 | N3: =Annual!AV114 -> 6000 | O3: =Annual!BA114 -> 6000 | P3: =Annual!BF114 -> 6000 | Q3: =Annual!BK114 -> 6000 | R3: =Annual!BP114 -> 6000
A4: 1962 | B4: ='Setup Page'!C19 -> Fines | C4: =SUMIFS('Income Entry'!$F$11:$F1000,'Income Entry'!$L$11:$L1000,B4,'Income Entry'!$S$11:$S1000,Monthly!$K$10,'Income Entry'!$T$11:$T1000,Monthly!$S$10) -> 0 | D4: =SUMIFS('Income Entry'!$H$11:$H1000,'Income Entry'!$L$11:$L1000,B4,'Income Entry'!$S$11:$S1000,Monthly!$K$10,'Income Entry'!$T$11:$T1000,Monthly!$S$10) -> 0 | E4: =SUMIFS('Income Entry'!$I$11:$I1000,'Income Entry'!$L$11:$L1000,B4,'Income Entry'!$S$11:$S1000,Monthly!$K$10,'Income Entry'!$T$11:$T1000,Monthly!$S$10) -> 0
A5: 1963 | B5: ='Setup Page'!C20 | C5: =SUMIFS('Income Entry'!$F$11:$F1000,'Income Entry'!$L$11:$L1000,B5,'Income Entry'!$S$11:$S1000,Monthly!$K$10,'Income Entry'!$T$11:$T1000,Monthly!$S$10) -> 0 | D5: =SUMIFS('Income Entry'!$H$11:$H1000,'Income Entry'!$L$11:$L1000,B5,'Income Entry'!$S$11:$S1000,Monthly!$K$10,'Income Entry'!$T$11:$T1000,Monthly!$S$10) -> 0 | E5: =SUMIFS('Income Entry'!$I$11:$I1000,'Income Entry'!$L$11:$L1000,B5,'Income Entry'!$S$11:$S1000,Monthly!$K$10,'Income Entry'!$T$11:$T1000,Monthly!$S$10) -> 0 | F5: I N C O M E | G5: =Annual!M61 -> 5000 | H5: =Annual!R61 -> 6550 | I5: =Annual!W61 -> 5000 | J5: =Annual!AB61 -> 8500 | K5: =Annual!AG61 -> 6920 | L5: =Annual!AL61 -> 5192.76 | M5: =Annual!AQ61 -> 12550 | N5: =Annual!AV61 -> 12100 | O5: =Annual!BA61 -> 20276.84 | P5: =Annual!BF61 -> 0 | Q5: =Annual!BK61 -> 0 | R5: =Annual!BP61 -> 0
A6: 1964 | B6: ='Setup Page'!C21 | C6: =SUMIFS('Income Entry'!$F$11:$F1000,'Income Entry'!$L$11:$L1000,B6,'Income Entry'!$S$11:$S1000,Monthly!$K$10,'Income Entry'!$T$11:$T1000,Monthly!$S$10) -> 0 | D6: =SUMIFS('Income Entry'!$H$11:$H1000,'Income Entry'!$L$11:$L1000,B6,'Income Entry'!$S$11:$S1000,Monthly!$K$10,'Income Entry'!$T$11:$T1000,Monthly!$S$10) -> 0 | E6: =SUMIFS('Income Entry'!$I$11:$I1000,'Income Entry'!$L$11:$L1000,B6,'Income Entry'!$S$11:$S1000,Monthly!$K$10,'Income Entry'!$T$11:$T1000,Monthly!$S$10) -> 0 | F6: E X P E N S E S | G6: =Annual!M106 -> 12.96 | H6: =Annual!R106 -> 14.4 | I6: =Annual!W106 -> 20 | J6: =Annual!AB106 -> 28.8 | K6: =Annual!AG106 -> 28.8 | L6: =Annual!AL106 -> 28.8 | M6: =Annual!AQ106 -> 28.8 | N6: =Annual!AV106 -> 127.8 | O6: =Annual!BA106 -> 0 | P6: =Annual!BF106 -> 28.8 | Q6: =Annual!BK106 -> 28.8 | R6: =Annual!BP106 -> 28.8
A7: 1965 | B7: ='Setup Page'!C22 | C7: =SUMIFS('Income Entry'!$F$11:$F1000,'Income Entry'!$L$11:$L1000,B7,'Income Entry'!$S$11:$S1000,Monthly!$K$10,'Income Entry'!$T$11:$T1000,Monthly!$S$10) -> 0 | D7: =SUMIFS('Income Entry'!$H$11:$H1000,'Income Entry'!$L$11:$L1000,B7,'Income Entry'!$S$11:$S1000,Monthly!$K$10,'Income Entry'!$T$11:$T1000,Monthly!$S$10) -> 0 | E7: =SUMIFS('Income Entry'!$I$11:$I1000,'Income Entry'!$L$11:$L1000,B7,'Income Entry'!$S$11:$S1000,Monthly!$K$10,'Income Entry'!$T$11:$T1000,Monthly!$S$10) -> 0
A8: 1966 | B8: ='Setup Page'!C23 | C8: =SUMIFS('Income Entry'!$F$11:$F1000,'Income Entry'!$L$11:$L1000,B8,'Income Entry'!$S$11:$S1000,Monthly!$K$10,'Income Entry'!$T$11:$T1000,Monthly!$S$10) -> 0 | D8: =SUMIFS('Income Entry'!$H$11:$H1000,'Income Entry'!$L$11:$L1000,B8,'Income Entry'!$S$11:$S1000,Monthly!$K$10,'Income Entry'!$T$11:$T1000,Monthly!$S$10) -> 0 | E8: =SUMIFS('Income Entry'!$I$11:$I1000,'Income Entry'!$L$11:$L1000,B8,'Income Entry'!$S$11:$S1000,Monthly!$K$10,'Income Entry'!$T$11:$T1000,Monthly!$S$10) -> 0 | F8: PAYMENT METHODS
A9: 1967 | B9: ='Setup Page'!C24 | C9: =SUMIFS('Income Entry'!$F$11:$F1000,'Income Entry'!$L$11:$L1000,B9,'Income Entry'!$S$11:$S1000,Monthly!$K$10,'Income Entry'!$T$11:$T1000,Monthly!$S$10) -> 0 | D9: =SUMIFS('Income Entry'!$H$11:$H1000,'Income Entry'!$L$11:$L1000,B9,'Income Entry'!$S$11:$S1000,Monthly!$K$10,'Income Entry'!$T$11:$T1000,Monthly!$S$10) -> 0 | E9: =SUMIFS('Income Entry'!$I$11:$I1000,'Income Entry'!$L$11:$L1000,B9,'Income Entry'!$S$11:$S1000,Monthly!$K$10,'Income Entry'!$T$11:$T1000,Monthly!$S$10) -> 0 | F9: ='Setup Page'!E10 -> Cash
A10: 1968 | B10: ='Setup Page'!C25 | C10: =SUMIFS('Income Entry'!$F$11:$F1000,'Income Entry'!$L$11:$L1000,B10,'Income Entry'!$S$11:$S1000,Monthly!$K$10,'Income Entry'!$T$11:$T1000,Monthly!$S$10) -> 0 | D10: =SUMIFS('Income Entry'!$H$11:$H1000,'Income Entry'!$L$11:$L1000,B10,'Income Entry'!$S$11:$S1000,Monthly!$K$10,'Income Entry'!$T$11:$T1000,Monthly!$S$10) -> 0 | E10: =SUMIFS('Income Entry'!$I$11:$I1000,'Income Entry'!$L$11:$L1000,B10,'Income Entry'!$S$11:$S1000,Monthly!$K$10,'Income Entry'!$T$11:$T1000,Monthly!$S$10) -> 0 | F10: ='Setup Page'!E11 -> Credit Card
A11: 1969 | B11: ='Setup Page'!C26 | C11: =SUMIFS('Income Entry'!$F$11:$F1000,'Income Entry'!$L$11:$L1000,B11,'Income Entry'!$S$11:$S1000,Monthly!$K$10,'Income Entry'!$T$11:$T1000,Monthly!$S$10) -> 0 | D11: =SUMIFS('Income Entry'!$H$11:$H1000,'Income Entry'!$L$11:$L1000,B11,'Income Entry'!$S$11:$S1000,Monthly!$K$10,'Income Entry'!$T$11:$T1000,Monthly!$S$10) -> 0 | E11: =SUMIFS('Income Entry'!$I$11:$I1000,'Income Entry'!$L$11:$L1000,B11,'Income Entry'!$S$11:$S1000,Monthly!$K$10,'Income Entry'!$T$11:$T1000,Monthly!$S$10) -> 0 | F11: ='Setup Page'!E12 -> Bank Account
A12: 1970 | B12: ='Setup Page'!C27 | C12: =SUMIFS('Income Entry'!$F$11:$F1000,'Income Entry'!$L$11:$L1000,B12,'Income Entry'!$S$11:$S1000,Monthly!$K$10,'Income Entry'!$T$11:$T1000,Monthly!$S$10) -> 0 | D12: =SUMIFS('Income Entry'!$H$11:$H1000,'Income Entry'!$L$11:$L1000,B12,'Income Entry'!$S$11:$S1000,Monthly!$K$10,'Income Entry'!$T$11:$T1000,Monthly!$S$10) -> 0 | E12: =SUMIFS('Income Entry'!$I$11:$I1000,'Income Entry'!$L$11:$L1000,B12,'Income Entry'!$S$11:$S1000,Monthly!$K$10,'Income Entry'!$T$11:$T1000,Monthly!$S$10) -> 0 | F12: ='Setup Page'!O10 -> Zelle
A13: 1971 | B13: ='Setup Page'!C28 | C13: =SUMIFS('Income Entry'!$F$11:$F1000,'Income Entry'!$L$11:$L1000,B13,'Income Entry'!$S$11:$S1000,Monthly!$K$10,'Income Entry'!$T$11:$T1000,Monthly!$S$10) -> 0 | D13: =SUMIFS('Income Entry'!$H$11:$H1000,'Income Entry'!$L$11:$L1000,B13,'Income Entry'!$S$11:$S1000,Monthly!$K$10,'Income Entry'!$T$11:$T1000,Monthly!$S$10) -> 0 | E13: =SUMIFS('Income Entry'!$I$11:$I1000,'Income Entry'!$L$11:$L1000,B13,'Income Entry'!$S$11:$S1000,Monthly!$K$10,'Income Entry'!$T$11:$T1000,Monthly!$S$10) -> 0 | F13: ='Setup Page'!O11
A14: 1972 | B14: ='Setup Page'!C29 | C14: =SUMIFS('Income Entry'!$F$11:$F1000,'Income Entry'!$L$11:$L1000,B14,'Income Entry'!$S$11:$S1000,Monthly!$K$10,'Income Entry'!$T$11:$T1000,Monthly!$S$10) -> 0 | D14: =SUMIFS('Income Entry'!$H$11:$H1000,'Income Entry'!$L$11:$L1000,B14,'Income Entry'!$S$11:$S1000,Monthly!$K$10,'Income Entry'!$T$11:$T1000,Monthly!$S$10) -> 0 | E14: =SUMIFS('Income Entry'!$I$11:$I1000,'Income Entry'!$L$11:$L1000,B14,'Income Entry'!$S$11:$S1000,Monthly!$K$10,'Income Entry'!$T$11:$T1000,Monthly!$S$10) -> 0 | F14: ='Setup Page'!O12
A15: 1973 | B15: ='Setup Page'!C30 | C15: =SUMIFS('Income Entry'!$F$11:$F1000,'Income Entry'!$L$11:$L1000,B15,'Income Entry'!$S$11:$S1000,Monthly!$K$10,'Income Entry'!$T$11:$T1000,Monthly!$S$10) -> 0 | D15: =SUMIFS('Income Entry'!$H$11:$H1000,'Income Entry'!$L$11:$L1000,B15,'Income Entry'!$S$11:$S1000,Monthly!$K$10,'Income Entry'!$T$11:$T1000,Monthly!$S$10) -> 0 | E15: =SUMIFS('Income Entry'!$I$11:$I1000,'Income Entry'!$L$11:$L1000,B15,'Income Entry'!$S$11:$S1000,Monthly!$K$10,'Income Entry'!$T$11:$T1000,Monthly!$S$10) -> 0 | F15: ='Setup Page'!Y10
A16: 1974 | B16: ='Setup Page'!C31 | C16: =SUMIFS('Income Entry'!$F$11:$F1000,'Income Entry'!$L$11:$L1000,B16,'Income Entry'!$S$11:$S1000,Monthly!$K$10,'Income Entry'!$T$11:$T1000,Monthly!$S$10) -> 0 | D16: =SUMIFS('Income Entry'!$H$11:$H1000,'Income Entry'!$L$11:$L1000,B16,'Income Entry'!$S$11:$S1000,Monthly!$K$10,'Income Entry'!$T$11:$T1000,Monthly!$S$10) -> 0 | E16: =SUMIFS('Income Entry'!$I$11:$I1000,'Income Entry'!$L$11:$L1000,B16,'Income Entry'!$S$11:$S1000,Monthly!$K$10,'Income Entry'!$T$11:$T1000,Monthly!$S$10) -> 0 | F16: ='Setup Page'!Y11
A17: 1975 | B17: ='Setup Page'!C32 | C17: =SUMIFS('Income Entry'!$F$11:$F1000,'Income Entry'!$L$11:$L1000,B17,'Income Entry'!$S$11:$S1000,Monthly!$K$10,'Income Entry'!$T$11:$T1000,Monthly!$S$10) -> 0 | D17: =SUMIFS('Income Entry'!$H$11:$H1000,'Income Entry'!$L$11:$L1000,B17,'Income Entry'!$S$11:$S1000,Monthly!$K$10,'Income Entry'!$T$11:$T1000,Monthly!$S$10) -> 0 | E17: =SUMIFS('Income Entry'!$I$11:$I1000,'Income Entry'!$L$11:$L1000,B17,'Income Entry'!$S$11:$S1000,Monthly!$K$10,'Income Entry'!$T$11:$T1000,Monthly!$S$10) -> 0 | F17: ='Setup Page'!Y12
A18: 1976 | B18: ='Setup Page'!C33 | C18: =SUMIFS('Income Entry'!$F$11:$F1000,'Income Entry'!$L$11:$L1000,B18,'Income Entry'!$S$11:$S1000,Monthly!$K$10,'Income Entry'!$T$11:$T1000,Monthly!$S$10) -> 0 | D18: =SUMIFS('Income Entry'!$H$11:$H1000,'Income Entry'!$L$11:$L1000,B18,'Income Entry'!$S$11:$S1000,Monthly!$K$10,'Income Entry'!$T$11:$T1000,Monthly!$S$10) -> 0 | E18: =SUMIFS('Income Entry'!$I$11:$I1000,'Income Entry'!$L$11:$L1000,B18,'Income Entry'!$S$11:$S1000,Monthly!$K$10,'Income Entry'!$T$11:$T1000,Monthly!$S$10) -> 0 | F18: ='Setup Page'!AI10
A19: 1977 | B19: ='Setup Page'!C34 | C19: =SUMIFS('Income Entry'!$F$11:$F1000,'Income Entry'!$L$11:$L1000,B19,'Income Entry'!$S$11:$S1000,Monthly!$K$10,'Income Entry'!$T$11:$T1000,Monthly!$S$10) -> 0 | D19: =SUMIFS('Income Entry'!$H$11:$H1000,'Income Entry'!$L$11:$L1000,B19,'Income Entry'!$S$11:$S1000,Monthly!$K$10,'Income Entry'!$T$11:$T1000,Monthly!$S$10) -> 0 | E19: =SUMIFS('Income Entry'!$I$11:$I1000,'Income Entry'!$L$11:$L1000,B19,'Income Entry'!$S$11:$S1000,Monthly!$K$10,'Income Entry'!$T$11:$T1000,Monthly!$S$10) -> 0 | F19: ='Setup Page'!AI11
A20: 1978 | B20: ='Setup Page'!C35 | C20: =SUMIFS('Income Entry'!$F$11:$F1000,'Income Entry'!$L$11:$L1000,B20,'Income Entry'!$S$11:$S1000,Monthly!$K$10,'Income Entry'!$T$11:$T1000,Monthly!$S$10) -> 0 | D20: =SUMIFS('Income Entry'!$H$11:$H1000,'Income Entry'!$L$11:$L1000,B20,'Income Entry'!$S$11:$S1000,Monthly!$K$10,'Income Entry'!$T$11:$T1000,Monthly!$S$10) -> 0 | E20: =SUMIFS('Income Entry'!$I$11:$I1000,'Income Entry'!$L$11:$L1000,B20,'Income Entry'!$S$11:$S1000,Monthly!$K$10,'Income Entry'!$T$11:$T1000,Monthly!$S$10) -> 0 | F20: ='Setup Page'!AI12
A21: 1979 | B21: ='Setup Page'!C36 | C21: =SUMIFS('Income Entry'!$F$11:$F1000,'Income Entry'!$L$11:$L1000,B21,'Income Entry'!$S$11:$S1000,Monthly!$K$10,'Income Entry'!$T$11:$T1000,Monthly!$S$10) -> 0 | D21: =SUMIFS('Income Entry'!$H$11:$H1000,'Income Entry'!$L$11:$L1000,B21,'Income Entry'!$S$11:$S1000,Monthly!$K$10,'Income Entry'!$T$11:$T1000,Monthly!$S$10) -> 0 | E21: =SUMIFS('Income Entry'!$I$11:$I1000,'Income Entry'!$L$11:$L1000,B21,'Income Entry'!$S$11:$S1000,Monthly!$K$10,'Income Entry'!$T$11:$T1000,Monthly!$S$10) -> 0
A22: 1980 | B22: ='Setup Page'!C37 | C22: =SUMIFS('Income Entry'!$F$11:$F1000,'Income Entry'!$L$11:$L1000,B22,'Income Entry'!$S$11:$S1000,Monthly!$K$10,'Income Entry'!$T$11:$T1000,Monthly!$S$10) -> 0 | D22: =SUMIFS('Income Entry'!$H$11:$H1000,'Income Entry'!$L$11:$L1000,B22,'Income Entry'!$S$11:$S1000,Monthly!$K$10,'Income Entry'!$T$11:$T1000,Monthly!$S$10) -> 0 | E22: =SUMIFS('Income Entry'!$I$11:$I1000,'Income Entry'!$L$11:$L1000,B22,'Income Entry'!$S$11:$S1000,Monthly!$K$10,'Income Entry'!$T$11:$T1000,Monthly!$S$10) -> 0
A23: 1981 | B23: ='Setup Page'!C38 | C23: =SUMIFS('Income Entry'!$F$11:$F1000,'Income Entry'!$L$11:$L1000,B23,'Income Entry'!$S$11:$S1000,Monthly!$K$10,'Income Entry'!$T$11:$T1000,Monthly!$S$10) -> 0 | D23: =SUMIFS('Income Entry'!$H$11:$H1000,'Income Entry'!$L$11:$L1000,B23,'Income Entry'!$S$11:$S1000,Monthly!$K$10,'Income Entry'!$T$11:$T1000,Monthly!$S$10) -> 0 | E23: =SUMIFS('Income Entry'!$I$11:$I1000,'Income Entry'!$L$11:$L1000,B23,'Income Entry'!$S$11:$S1000,Monthly!$K$10,'Income Entry'!$T$11:$T1000,Monthly!$S$10) -> 0
A24: 1982 | B24: ='Setup Page'!C39 | C24: =SUMIFS('Income Entry'!$F$11:$F1000,'Income Entry'!$L$11:$L1000,B24,'Income Entry'!$S$11:$S1000,Monthly!$K$10,'Income Entry'!$T$11:$T1000,Monthly!$S$10) -> 0 | D24: =SUMIFS('Income Entry'!$H$11:$H1000,'Income Entry'!$L$11:$L1000,B24,'Income Entry'!$S$11:$S1000,Monthly!$K$10,'Income Entry'!$T$11:$T1000,Monthly!$S$10) -> 0 | E24: =SUMIFS('Income Entry'!$I$11:$I1000,'Income Entry'!$L$11:$L1000,B24,'Income Entry'!$S$11:$S1000,Monthly!$K$10,'Income Entry'!$T$11:$T1000,Monthly!$S$10) -> 0
A25: 1983 | B25: ='Setup Page'!C40 | C25: =SUMIFS('Income Entry'!$F$11:$F1000,'Income Entry'!$L$11:$L1000,B25,'Income Entry'!$S$11:$S1000,Monthly!$K$10,'Income Entry'!$T$11:$T1000,Monthly!$S$10) -> 0 | D25: =SUMIFS('Income Entry'!$H$11:$H1000,'Income Entry'!$L$11:$L1000,B25,'Income Entry'!$S$11:$S1000,Monthly!$K$10,'Income Entry'!$T$11:$T1000,Monthly!$S$10) -> 0 | E25: =SUMIFS('Income Entry'!$I$11:$I1000,'Income Entry'!$L$11:$L1000,B25,'Income Entry'!$S$11:$S1000,Monthly!$K$10,'Income Entry'!$T$11:$T1000,Monthly!$S$10) -> 0
A26: 1984 | B26: ='Setup Page'!C41 | C26: =SUMIFS('Income Entry'!$F$11:$F1000,'Income Entry'!$L$11:$L1000,B26,'Income Entry'!$S$11:$S1000,Monthly!$K$10,'Income Entry'!$T$11:$T1000,Monthly!$S$10) -> 0 | D26: =SUMIFS('Income Entry'!$H$11:$H1000,'Income Entry'!$L$11:$L1000,B26,'Income Entry'!$S$11:$S1000,Monthly!$K$10,'Income Entry'!$T$11:$T1000,Monthly!$S$10) -> 0 | E26: =SUMIFS('Income Entry'!$I$11:$I1000,'Income Entry'!$L$11:$L1000,B26,'Income Entry'!$S$11:$S1000,Monthly!$K$10,'Income Entry'!$T$11:$T1000,Monthly!$S$10) -> 0
A27: 1985 | B27: ='Setup Page'!C42 | C27: =SUMIFS('Income Entry'!$F$11:$F1000,'Income Entry'!$L$11:$L1000,B27,'Income Entry'!$S$11:$S1000,Monthly!$K$10,'Income Entry'!$T$11:$T1000,Monthly!$S$10) -> 0 | D27: =SUMIFS('Income Entry'!$H$11:$H1000,'Income Entry'!$L$11:$L1000,B27,'Income Entry'!$S$11:$S1000,Monthly!$K$10,'Income Entry'!$T$11:$T1000,Monthly!$S$10) -> 0 | E27: =SUMIFS('Income Entry'!$I$11:$I1000,'Income Entry'!$L$11:$L1000,B27,'Income Entry'!$S$11:$S1000,Monthly!$K$10,'Income Entry'!$T$11:$T1000,Monthly!$S$10) -> 0
A28: 1986 | B28: ='Setup Page'!C43 | C28: =SUMIFS('Income Entry'!$F$11:$F1000,'Income Entry'!$L$11:$L1000,B28,'Income Entry'!$S$11:$S1000,Monthly!$K$10,'Income Entry'!$T$11:$T1000,Monthly!$S$10) -> 0 | D28: =SUMIFS('Income Entry'!$H$11:$H1000,'Income Entry'!$L$11:$L1000,B28,'Income Entry'!$S$11:$S1000,Monthly!$K$10,'Income Entry'!$T$11:$T1000,Monthly!$S$10) -> 0 | E28: =SUMIFS('Income Entry'!$I$11:$I1000,'Income Entry'!$L$11:$L1000,B28,'Income Entry'!$S$11:$S1000,Monthly!$K$10,'Income Entry'!$T$11:$T1000,Monthly!$S$10) -> 0
A29: 1987 | B29: ='Setup Page'!C44 | C29: =SUMIFS('Income Entry'!$F$11:$F1000,'Income Entry'!$L$11:$L1000,B29,'Income Entry'!$S$11:$S1000,Monthly!$K$10,'Income Entry'!$T$11:$T1000,Monthly!$S$10) -> 0 | D29: =SUMIFS('Income Entry'!$H$11:$H1000,'Income Entry'!$L$11:$L1000,B29,'Income Entry'!$S$11:$S1000,Monthly!$K$10,'Income Entry'!$T$11:$T1000,Monthly!$S$10) -> 0 | E29: =SUMIFS('Income Entry'!$I$11:$I1000,'Income Entry'!$L$11:$L1000,B29,'Income Entry'!$S$11:$S1000,Monthly!$K$10,'Income Entry'!$T$11:$T1000,Monthly!$S$10) -> 0
A30: 1988 | B30: ='Setup Page'!C45 | C30: =SUMIFS('Income Entry'!$F$11:$F1000,'Income Entry'!$L$11:$L1000,B30,'Income Entry'!$S$11:$S1000,Monthly!$K$10,'Income Entry'!$T$11:$T1000,Monthly!$S$10) -> 0 | D30: =SUMIFS('Income Entry'!$H$11:$H1000,'Income Entry'!$L$11:$L1000,B30,'Income Entry'!$S$11:$S1000,Monthly!$K$10,'Income Entry'!$T$11:$T1000,Monthly!$S$10) -> 0 | E30: =SUMIFS('Income Entry'!$I$11:$I1000,'Income Entry'!$L$11:$L1000,B30,'Income Entry'!$S$11:$S1000,Monthly!$K$10,'Income Entry'!$T$11:$T1000,Monthly!$S$10) -> 0
A31: 1989 | B31: ='Setup Page'!C46 | C31: =SUMIFS('Income Entry'!$F$11:$F1000,'Income Entry'!$L$11:$L1000,B31,'Income Entry'!$S$11:$S1000,Monthly!$K$10,'Income Entry'!$T$11:$T1000,Monthly!$S$10) -> 0 | D31: =SUMIFS('Income Entry'!$H$11:$H1000,'Income Entry'!$L$11:$L1000,B31,'Income Entry'!$S$11:$S1000,Monthly!$K$10,'Income Entry'!$T$11:$T1000,Monthly!$S$10) -> 0 | E31: =SUMIFS('Income Entry'!$I$11:$I1000,'Income Entry'!$L$11:$L1000,B31,'Income Entry'!$S$11:$S1000,Monthly!$K$10,'Income Entry'!$T$11:$T1000,Monthly!$S$10) -> 0
A32: 1990 | B32: ='Setup Page'!C47 | C32: =SUMIFS('Income Entry'!$F$11:$F1000,'Income Entry'!$L$11:$L1000,B32,'Income Entry'!$S$11:$S1000,Monthly!$K$10,'Income Entry'!$T$11:$T1000,Monthly!$S$10) -> 0 | D32: =SUMIFS('Income Entry'!$H$11:$H1000,'Income Entry'!$L$11:$L1000,B32,'Income Entry'!$S$11:$S1000,Monthly!$K$10,'Income Entry'!$T$11:$T1000,Monthly!$S$10) -> 0 | E32: =SUMIFS('Income Entry'!$I$11:$I1000,'Income Entry'!$L$11:$L1000,B32,'Income Entry'!$S$11:$S1000,Monthly!$K$10,'Income Entry'!$T$11:$T1000,Monthly!$S$10) -> 0
A33: 1991 | B33: ='Setup Page'!C48 | C33: =SUMIFS('Income Entry'!$F$11:$F1000,'Income Entry'!$L$11:$L1000,B33,'Income Entry'!$S$11:$S1000,Monthly!$K$10,'Income Entry'!$T$11:$T1000,Monthly!$S$10) -> 0 | D33: =SUMIFS('Income Entry'!$H$11:$H1000,'Income Entry'!$L$11:$L1000,B33,'Income Entry'!$S$11:$S1000,Monthly!$K$10,'Income Entry'!$T$11:$T1000,Monthly!$S$10) -> 0 | E33: =SUMIFS('Income Entry'!$I$11:$I1000,'Income Entry'!$L$11:$L1000,B33,'Income Entry'!$S$11:$S1000,Monthly!$K$10,'Income Entry'!$T$11:$T1000,Monthly!$S$10) -> 0
A34: 1992 | B34: ='Setup Page'!C49 | C34: =SUMIFS('Income Entry'!$F$11:$F1000,'Income Entry'!$L$11:$L1000,B34,'Income Entry'!$S$11:$S1000,Monthly!$K$10,'Income Entry'!$T$11:$T1000,Monthly!$S$10) -> 0 | D34: =SUMIFS('Income Entry'!$H$11:$H1000,'Income Entry'!$L$11:$L1000,B34,'Income Entry'!$S$11:$S1000,Monthly!$K$10,'Income Entry'!$T$11:$T1000,Monthly!$S$10) -> 0 | E34: =SUMIFS('Income Entry'!$I$11:$I1000,'Income Entry'!$L$11:$L1000,B34,'Income Entry'!$S$11:$S1000,Monthly!$K$10,'Income Entry'!$T$11:$T1000,Monthly!$S$10) -> 0
A35: 1993 | B35: ='Setup Page'!C50 | C35: =SUMIFS('Income Entry'!$F$11:$F1000,'Income Entry'!$L$11:$L1000,B35,'Income Entry'!$S$11:$S1000,Monthly!$K$10,'Income Entry'!$T$11:$T1000,Monthly!$S$10) -> 0 | D35: =SUMIFS('Income Entry'!$H$11:$H1000,'Income Entry'!$L$11:$L1000,B35,'Income Entry'!$S$11:$S1000,Monthly!$K$10,'Income Entry'!$T$11:$T1000,Monthly!$S$10) -> 0 | E35: =SUMIFS('Income Entry'!$I$11:$I1000,'Income Entry'!$L$11:$L1000,B35,'Income Entry'!$S$11:$S1000,Monthly!$K$10,'Income Entry'!$T$11:$T1000,Monthly!$S$10) -> 0
A36: 1994 | B36: ='Setup Page'!C51 | C36: =SUMIFS('Income Entry'!$F$11:$F1000,'Income Entry'!$L$11:$L1000,B36,'Income Entry'!$S$11:$S1000,Monthly!$K$10,'Income Entry'!$T$11:$T1000,Monthly!$S$10) -> 0 | D36: =SUMIFS('Income Entry'!$H$11:$H1000,'Income Entry'!$L$11:$L1000,B36,'Income Entry'!$S$11:$S1000,Monthly!$K$10,'Income Entry'!$T$11:$T1000,Monthly!$S$10) -> 0 | E36: =SUMIFS('Income Entry'!$I$11:$I1000,'Income Entry'!$L$11:$L1000,B36,'Income Entry'!$S$11:$S1000,Monthly!$K$10,'Income Entry'!$T$11:$T1000,Monthly!$S$10) -> 0
A37: 1995 | B37: ='Setup Page'!C52 | C37: =SUMIFS('Income Entry'!$F$11:$F1000,'Income Entry'!$L$11:$L1000,B37,'Income Entry'!$S$11:$S1000,Monthly!$K$10,'Income Entry'!$T$11:$T1000,Monthly!$S$10) -> 0 | D37: =SUMIFS('Income Entry'!$H$11:$H1000,'Income Entry'!$L$11:$L1000,B37,'Income Entry'!$S$11:$S1000,Monthly!$K$10,'Income Entry'!$T$11:$T1000,Monthly!$S$10) -> 0 | E37: =SUMIFS('Income Entry'!$I$11:$I1000,'Income Entry'!$L$11:$L1000,B37,'Income Entry'!$S$11:$S1000,Monthly!$K$10,'Income Entry'!$T$11:$T1000,Monthly!$S$10) -> 0
A38: 1996 | B38: ='Setup Page'!C53 | C38: =SUMIFS('Income Entry'!$F$11:$F1000,'Income Entry'!$L$11:$L1000,B38,'Income Entry'!$S$11:$S1000,Monthly!$K$10,'Income Entry'!$T$11:$T1000,Monthly!$S$10) -> 0 | D38: =SUMIFS('Income Entry'!$H$11:$H1000,'Income Entry'!$L$11:$L1000,B38,'Income Entry'!$S$11:$S1000,Monthly!$K$10,'Income Entry'!$T$11:$T1000,Monthly!$S$10) -> 0 | E38: =SUMIFS('Income Entry'!$I$11:$I1000,'Income Entry'!$L$11:$L1000,B38,'Income Entry'!$S$11:$S1000,Monthly!$K$10,'Income Entry'!$T$11:$T1000,Monthly!$S$10) -> 0
A39: 1997 | B39: ='Setup Page'!C54 | C39: =SUMIFS('Income Entry'!$F$11:$F1000,'Income Entry'!$L$11:$L1000,B39,'Income Entry'!$S$11:$S1000,Monthly!$K$10,'Income Entry'!$T$11:$T1000,Monthly!$S$10) -> 0 | D39: =SUMIFS('Income Entry'!$H$11:$H1000,'Income Entry'!$L$11:$L1000,B39,'Income Entry'!$S$11:$S1000,Monthly!$K$10,'Income Entry'!$T$11:$T1000,Monthly!$S$10) -> 0 | E39: =SUMIFS('Income Entry'!$I$11:$I1000,'Income Entry'!$L$11:$L1000,B39,'Income Entry'!$S$11:$S1000,Monthly!$K$10,'Income Entry'!$T$11:$T1000,Monthly!$S$10) -> 0
A40: 1998 | B40: ='Setup Page'!C55 | C40: =SUMIFS('Income Entry'!$F$11:$F1000,'Income Entry'!$L$11:$L1000,B40,'Income Entry'!$S$11:$S1000,Monthly!$K$10,'Income Entry'!$T$11:$T1000,Monthly!$S$10) -> 0 | D40: =SUMIFS('Income Entry'!$H$11:$H1000,'Income Entry'!$L$11:$L1000,B40,'Income Entry'!$S$11:$S1000,Monthly!$K$10,'Income Entry'!$T$11:$T1000,Monthly!$S$10) -> 0 | E40: =SUMIFS('Income Entry'!$I$11:$I1000,'Income Entry'!$L$11:$L1000,B40,'Income Entry'!$S$11:$S1000,Monthly!$K$10,'Income Entry'!$T$11:$T1000,Monthly!$S$10) -> 0
...

Sheet READ ME - Instructions
U2: Explore SerenatasEssentials:
B3: I N S T R U C T I O N S | U3: Discover valuable tools at our other shop for everyday use at SerenatasEssentials. Open the door to new opportunities and discover the ideal tools to elevate your personal endeavors.
B5: - B O O K K E E P I N G G U I D E -
U6: Don't miss out - visit SerenatasEssentials today!
B8: S E R E N A T A S J O U R N E Y | U8: L E T ' S S T A R T
C10: Welcome to your new bookkeeping spreadsheet! | U10: With a few important things...
C12: We are excited to have you here and confident that this template will simplify your financial record-keeping process. Our mission is to provide you with an easy-to-use tool to help you stay on top of your business's financial health and make informed decisions based on accurate data. | V12: This bookkeeping template is for informational purposes only and Serenatas Journey cannot provide any financial, tax, or legal advice. Before making any financial decisions, please do your own research and consult with a licensed financial advisor if necessary. Serenatas Journey will not be held responsible for any costs, losses, damages, or injuries that may result from the use of this spreadsheet.
C17: With this bookkeeping spreadsheet, you can efficiently track your income, expenses, and cash flow, ensuring that your finances are organized and up-to-date. We believe that by taking control of your bookkeeping, you can make better financial decisions and focus on growing your business.
V18: This bookkeeping template is copyrighted by Serenatas Journey and is for personal use only. Commercial or public use of any kind is strictly prohibited, including reselling, sharing, reproducing, or distributing the product, either in part or in full, with or without modifications.
C22: Thank you for choosing our bookkeeping template. We are dedicated to supporting you in managing your finances, and we're always here to answer any questions or concerns you may have. Let's work together to take your business to the next level.
V23: Serenatas Journey is not affiliated with Google Sheets in any way.
V25: Please note that this bookkeeping template can only be used on Google Sheets and is not compatible with Excel. A Google account is required to access the spreadsheet.
J28: Best regards, Anna and her Team | V28: Due to the nature of digital downloads, all sales for this bookkeeping template are final and no returns, exchanges, or cancellations will be accepted.
B32: M A K E Y O U R O W N E D I T A B L E C O P Y | U32: M O S T I M P O R T A N T I N S T R U C T I O N S
C34: To begin working towards your financial goals, it's important to have your own personal, editable copy of the bookkeeping template.
V35: 1. Refer to the Instructions tab for clarification on the bookkeeping template's workings.
C37: It's easy. | V37: 2. Only edit cells that are not color-coded.
C38: Go to the 'File' menu and click on 'Make a Copy'. | V38: 3. When entering transactions, ensure that mandatory fields are filled out, those are Date, Category, and Total amount.
V40: 4. Clear the data within rows and columns, but DO NOT delete them.
C46: IMPORTANT NOTE: PLEASE DO NOT REQUEST 'EDIT' ACCESS
B49: S E T U P P A G E
U52: C U R R E N C Y
U53: From the list of 11 options, choose the currency you would like to use throughout the entire template. If your desired currency is not listed, please contact us.
U56: M O N T H
U57: Select the starting month from the drop-down menu.
U59: Y E A R
U60: This template can be used for any year of your choosing. Simply use the drop-down menu to select the year for which you are starting your bookkeeping journey.
U63: P R O F I T G O A L
U64: Is a feature of the bookkeeping template that allows you to define a specific target profit for your business each month.
C67: C A T E G O R I E S
C68: Simply enter your income and expense categories, with the flexibility to create up to 20 categories in each section. This feature allows you to easily categorize your transactions and gain a better understanding of your business's financial performance. By customizing your categories, you can tailor the bookkeeping template to fit your unique business needs and goals.
B73: I N C O M E / E X P E N S E S E N T R Y
C88: In the Income & Expenses Entry tab of our bookkeeping Google Sheet template, you'll find three mandatory column entries: Date, Category or Product / Service, and Total Amount. These fields ensure that you have a clear record of your business's income & expenses, making it easier for you to track your financial performance. We've also included optional fields like ID, Tax, and fields for Client Tracking in the income Entry, which you can fill in for your convenience. Additionally, you can add a Description and Notes to provide more context for each income & expense transaction. Our goal is to provide you with a customizable and user-friendly tool to streamline your bookkeeping process and make it easy for you to stay on top of your business finances
C93: H I G H L I G H T C A T E G O R Y | U93: T A X R A T E
C94: With this feature, you can highlight a particular income or expense category, and all transactions within that category will be automatically highlighted in the sheet. This feature provides you with a quick and convenient way to search for and analyze specific categories of transactions, saving you time and effort in your bookkeeping process. | U94: Our bookkeeping Google Sheet template offers a convenient and flexible tax rate feature that allows you to set a default tax rate for your business transactions, while also providing the flexibility to modify the tax rate for specific transactions as needed. With this feature, you can set a common tax rate (such as 10%) in the upper right cell, and this rate will automatically apply to all transactions unless you specify a different tax rate in a particular transaction entry.
C99: N E T A M O U N T / T A X A M O U N T
C100: The Net and Tax Amount columns are designed to automatically calculate the net and tax amounts for each transaction based on the total amount and tax rate you've entered, or the default tax rate you have set. This feature saves you time and effort in your bookkeeping process. | U100: T O T A L S
U101: This section provides a fast and convenient way to view your financial data at a glance, including the total amount, net amount, and tax amount for all transactions combined.
B106: M O N T H L Y O V E R V I E W
W109: The Monthly Overview tab in our Bookkeeping Google Sheet template provides a comprehensive summary of your financial data for each month. Here, you can view the total income, total expenses, net income, and tax amount for each month, as well as the percentage of income and expenses for each category.
...

Sheet Setup Page
V2: P I C K Y O U R C U R R E N C Y | AD2: P I C K Y O U R S T A R T M O N T H | AM2: P I C K T H E Y E A R
B3: S E T U P
W4: $ | AD4: July | AM4: 2023
B5: - D A S H B O A R D -
B8: P A Y M E N T M E T H O D S / A C C O U N T S
D10: 1 . | E10: Cash | N10: 4 . | O10: Zelle | X10: 7 . | AH10: 10 .
D11: 2 . | E11: Credit Card | N11: 5 . | X11: 8 . | AH11: 11 .
D12: 3 . | E12: Bank Account | N12: 6 . | X12: 9 . | AH12: 12 .
B15: S E T Y O U R C A T E G O R I E S | AC15: S E T Y O U R M O N T H L Y P R O F I T G O A L S
B17: P R O D U C T S / S E R V I C E S | O17: E X P E N S E | AC17: M O N T H | AK17: G O A L A M O U N T
C18: Investment | P18: Virtual Address | AC18: =DATE(AM4,MONTH(AD4&1),1) -> 45108 | AK18: =IF(AM18="","",$W$4) -> $ | AM18: 0 | AS18: =AC18 -> 45108 | AT18: =AM18 -> 0 | AU18: =month(AC18) -> 7 | AV18: =year(AC18) -> 2023 | AW18: =UPPER(TEXT('Setup Page'!AC18,"mmm yy")) -> JUL 23
C19: Fines | P19: Legal Zoom | AC19: =edate(AC18,1) -> 45139 | AK19: =IF(AM19="","",$W$4) -> $ | AM19: 0 | AS19: =AC19 -> 45139 | AT19: =AM19 -> 0 | AU19: =month(AC19) -> 8 | AV19: =year(AC19) -> 2023 | AW19: =UPPER(TEXT('Setup Page'!AC19,"mmm yy")) -> AUG 23
P20: Google GSuite | AC20: =edate(AC19,1) -> 45170 | AK20: =IF(AM20="","",$W$4) -> $ | AM20: 2400 | AS20: =AC20 -> 45170 | AT20: =AM20 -> 2400 | AU20: =month(AC20) -> 9 | AV20: =year(AC20) -> 2023 | AW20: =UPPER(TEXT('Setup Page'!AC20,"mmm yy")) -> SEP 23
AC21: =edate(AC20,1) -> 45200 | AK21: =IF(AM21="","",$W$4) -> $ | AM21: 2400 | AS21: =AC21 -> 45200 | AT21: =AM21 -> 2400 | AU21: =month(AC21) -> 10 | AV21: =year(AC21) -> 2023 | AW21: =UPPER(TEXT('Setup Page'!AC21,"mmm yy")) -> OCT 23
AC22: =edate(AC21,1) -> 45231 | AK22: =IF(AM22="","",$W$4) -> $ | AM22: 2400 | AS22: =AC22 -> 45231 | AT22: =AM22 -> 2400 | AU22: =month(AC22) -> 11 | AV22: =year(AC22) -> 2023 | AW22: =UPPER(TEXT('Setup Page'!AC22,"mmm yy")) -> NOV 23
AC23: =edate(AC22,1) -> 45261 | AK23: =IF(AM23="","",$W$4) -> $ | AM23: 6000 | AS23: =AC23 -> 45261 | AT23: =AM23 -> 6000 | AU23: =month(AC23) -> 12 | AV23: =year(AC23) -> 2023 | AW23: =UPPER(TEXT('Setup Page'!AC23,"mmm yy")) -> DEC 23
AC24: =edate(AC23,1) -> 45292 | AK24: =IF(AM24="","",$W$4) -> $ | AM24: 6000 | AS24: =AC24 -> 45292 | AT24: =AM24 -> 6000 | AU24: =month(AC24) -> 1 | AV24: =year(AC24) -> 2024 | AW24: =UPPER(TEXT('Setup Page'!AC24,"mmm yy")) -> JAN 24
AC25: =edate(AC24,1) -> 45323 | AK25: =IF(AM25="","",$W$4) -> $ | AM25: 6000 | AS25: =AC25 -> 45323 | AT25: =AM25 -> 6000 | AU25: =month(AC25) -> 2 | AV25: =year(AC25) -> 2024 | AW25: =UPPER(TEXT('Setup Page'!AC25,"mmm yy")) -> FEB 24
AC26: =edate(AC25,1) -> 45352 | AK26: =IF(AM26="","",$W$4) -> $ | AM26: 6000 | AS26: =AC26 -> 45352 | AT26: =AM26 -> 6000 | AU26: =month(AC26) -> 3 | AV26: =year(AC26) -> 2024 | AW26: =UPPER(TEXT('Setup Page'!AC26,"mmm yy")) -> MAR 24
AC27: =edate(AC26,1) -> 45383 | AK27: =IF(AM27="","",$W$4) -> $ | AM27: 6000 | AS27: =AC27 -> 45383 | AT27: =AM27 -> 6000 | AU27: =month(AC27) -> 4 | AV27: =year(AC27) -> 2024 | AW27: =UPPER(TEXT('Setup Page'!AC27,"mmm yy")) -> APR 24
AC28: =edate(AC27,1) -> 45413 | AK28: =IF(AM28="","",$W$4) -> $ | AM28: 6000 | AS28: =AC28 -> 45413 | AT28: =AM28 -> 6000 | AU28: =month(AC28) -> 5 | AV28: =year(AC28) -> 2024 | AW28: =UPPER(TEXT('Setup Page'!AC28,"mmm yy")) -> MAY 24
AC29: =edate(AC28,1) -> 45444 | AK29: =IF(AM29="","",$W$4) -> $ | AM29: 6000 | AS29: =AC29 -> 45444 | AT29: =AM29 -> 6000 | AU29: =month(AC29) -> 6 | AV29: =year(AC29) -> 2024 | AW29: =UPPER(TEXT('Setup Page'!AC29,"mmm yy")) -> JUN 24
AC31: A N N U A L P R O F I T G O A L
AE33: =W4 -> $ | AG33: =SUM(AM18:AQ29) -> 49200
AC36: I N C O M E E N T R Y | AK36: E X P E N S E E N T R Y
C58: EMPTY | P58: EMPTY

Sheet Income Entry
I2: H I G H L I G H T C L I E N T S N A M E / L A S T N A M E | L2: H I G H L I G H T P R O D U C T / S E R V I C E | P2: M O S T C O M M O N T A X R A T E ( % )
B3: I N C O M E
I4: F I R S T N A M E : | J4: Oluwafemi | L4: EMPTY | P4: 0
B5: - E N T R Y - | I5: L A S T N A M E :
E8: T O T A L I N C O M E | F8: =SUM(F11:F1002) -> 239652.06 | H8: =SUM(H11:H1002) -> 239652.06 | I8: =SUM(I11:I1002) -> 0
B9: I D | C9: D A T E | D9: F I R S T N A M E | E9: L A S T N A M E | F9: T O T A L A M O U N T | G9: T A X % | H9: N E T A M O U N T | I9: T A X A M O U N T | J9: P A I D W I T H | L9: P R O D U C T / S E R V I C E | M9: D E S C R I P T I O N | O9: A D D R E S S | P9: T E L . N U M B E R | Q9: E - M A I L
H10: =F10-I10 -> 0 | I10: =F10-(F10/(1+IF(G10="",$P$4,G10))) -> 0
B11: 100001 | C11: 45041 | D11: Oladapo | E11: Ajala | F11: 400 | H11: =F11-I11 -> 400 | I11: =F11-(F11/(1+IF(G11="",$P$4,G11))) -> 0 | J11: Zelle | L11: Investment | S11: =IF(C11="","",MONTH(C11)) -> 4 | T11: =IF(C11="","",YEAR(C11)) -> 2023
B12: =B11+1 -> 100002 | C12: 45033 | D12: Temitope | E12: Ajibola | F12: 200 | H12: =F12-I12 -> 200 | I12: =F12-(F12/(1+IF(G12="",$P$4,G12))) -> 0 | J12: Zelle | L12: Investment | S12: =IF(C12="","",MONTH(C12)) -> 4 | T12: =IF(C12="","",YEAR(C12)) -> 2023
B13: =B12+1 -> 100003 | C13: 45011 | D13: Abiodun | E13: Akindele | F13: 200 | H13: =F13-I13 -> 200 | I13: =F13-(F13/(1+IF(G13="",$P$4,G13))) -> 0 | J13: Zelle | L13: Investment | S13: =IF(C13="","",MONTH(C13)) -> 3 | T13: =IF(C13="","",YEAR(C13)) -> 2023
B14: =B13+1 -> 100004 | C14: 45005 | D14: Olurotimi | E14: Dosumu | F14: 200 | H14: =F14-I14 -> 200 | I14: =F14-(F14/(1+IF(G14="",$P$4,G14))) -> 0 | J14: Zelle | L14: Investment | S14: =IF(C14="","",MONTH(C14)) -> 3 | T14: =IF(C14="","",YEAR(C14)) -> 2023
B15: =B14+1 -> 100005 | C15: 44993 | D15: Oluwafemi | E15: Durojaiye | F15: 200 | H15: =F15-I15 -> 200 | I15: =F15-(F15/(1+IF(G15="",$P$4,G15))) -> 0 | J15: Zelle | L15: Investment | S15: =IF(C15="","",MONTH(C15)) -> 3 | T15: =IF(C15="","",YEAR(C15)) -> 2023
B16: =B15+1 -> 100006 | C16: 44993 | D16: Olatunji | E16: Ilori | F16: 200 | H16: =F16-I16 -> 200 | I16: =F16-(F16/(1+IF(G16="",$P$4,G16))) -> 0 | J16: Zelle | L16: Investment | S16: =IF(C16="","",MONTH(C16)) -> 3 | T16: =IF(C16="","",YEAR(C16)) -> 2023
B17: =B16+1 -> 100007 | C17: 44994 | D17: Oluremi | E17: Makinde | F17: 200 | H17: =F17-I17 -> 200 | I17: =F17-(F17/(1+IF(G17="",$P$4,G17))) -> 0 | J17: Zelle | L17: Investment | S17: =IF(C17="","",MONTH(C17)) -> 3 | T17: =IF(C17="","",YEAR(C17)) -> 2023
B18: =B17+1 -> 100008 | C18: 44993 | D18: Jamiu | E18: Momodu | F18: 200 | H18: =F18-I18 -> 200 | I18: =F18-(F18/(1+IF(G18="",$P$4,G18))) -> 0 | J18: Zelle | L18: Investment | S18: =IF(C18="","",MONTH(C18)) -> 3 | T18: =IF(C18="","",YEAR(C18)) -> 2023
B19: =B18+1 -> 100009 | C19: 44996 | D19: Opeyemi | E19: Olomola | F19: 200 | H19: =F19-I19 -> 200 | I19: =F19-(F19/(1+IF(G19="",$P$4,G19))) -> 0 | J19: Zelle | L19: Investment | S19: =IF(C19="","",MONTH(C19)) -> 3 | T19: =IF(C19="","",YEAR(C19)) -> 2023
B20: =B19+1 -> 100010 | C20: 45013 | D20: Temitope | E20: Olutola | F20: 200 | H20: =F20-I20 -> 200 | I20: =F20-(F20/(1+IF(G20="",$P$4,G20))) -> 0 | J20: Zelle | L20: Investment | S20: =IF(C20="","",MONTH(C20)) -> 3 | T20: =IF(C20="","",YEAR(C20)) -> 2023
B21: =B20+1 -> 100011 | C21: 45010 | D21: Olumuyiwa | E21: Shoneye | F21: 200 | H21: =F21-I21 -> 200 | I21: =F21-(F21/(1+IF(G21="",$P$4,G21))) -> 0 | J21: Zelle | L21: Investment | S21: =IF(C21="","",MONTH(C21)) -> 3 | T21: =IF(C21="","",YEAR(C21)) -> 2023
B22: =B21+1 -> 100012 | C22: 45038 | D22: Dimeji | E22: Sule | F22: 400 | H22: =F22-I22 -> 400 | I22: =F22-(F22/(1+IF(G22="",$P$4,G22))) -> 0 | J22: Zelle | L22: Investment | S22: =IF(C22="","",MONTH(C22)) -> 4 | T22: =IF(C22="","",YEAR(C22)) -> 2023
B23: =B22+1 -> 100013 | C23: 44995 | D23: Temitope | E23: Ajibola | F23: 200 | H23: =F23-I23 -> 200 | I23: =F23-(F23/(1+IF(G23="",$P$4,G23))) -> 0 | J23: Zelle | L23: Investment | S23: =IF(C23="","",MONTH(C23)) -> 3 | T23: =IF(C23="","",YEAR(C23)) -> 2023
... B69: =B68+1 -> 100059 | C69: 45147 | D69: Dimeji | E69: Sule | F69: 500 | H69: =F69-I69 -> 500 | I69: =F69-(F69/(1+IF(G69="",$P$4,G69))) -> 0 | J69: Zelle | L69: Investment | S69: =IF(C69="","",MONTH(C69)) -> 8 | T69: =IF(C69="","",YEAR(C69)) -> 2023
B70: =B69+1 -> 100060 | C70: 45153 | D70: Oluremi | E70: Makinde | F70: 500 | H70: 500 | I70: =F70-(F70/(1+IF(G70="",$P$4,G70))) -> 0 | J70: Zelle | L70: Investment | S70: =IF(C70="","",MONTH(C70)) -> 8 | T70: =IF(C70="","",YEAR(C70)) -> 2023
B71: =B70+1 -> 100061 | C71: 45154 | D71: Oluwafemi | E71: Durojaiye | F71: 500 | H71: =F71-I71 -> 500 | I71: =F71-(F71/(1+IF(G71="",$P$4,G71))) -> 0 | J71: Zelle | L71: Investment | S71: =IF(C71="","",MONTH(C71)) -> 8 | T71: =IF(C71="","",YEAR(C71)) -> 2023
B72: =B71+1 -> 100062 | C72: 45154 | D72: Dimeji | E72: Sule | F72: 500 | H72: =F72-I72 -> 500 | I72: =F72-(F72/(1+IF(G72="",$P$4,G72))) -> 0 | J72: Zelle | L72: Investment | S72: =IF(C72="","",MONTH(C72)) -> 8 | T72: =IF(C72="","",YEAR(C72)) -> 2023
B73: =B72+1 -> 100063 | C73: 45155 | D73: Oladapo | E73: Ajala | F73: 500 | H73: =F73-I73 -> 500 | I73: =F73-(F73/(1+IF(G73="",$P$4,G73))) -> 0 | J73: Zelle | L73: Investment | S73: =IF(C73="","",MONTH(C73)) -> 8 | T73: =IF(C73="","",YEAR(C73)) -> 2023
B74: =B73+1 -> 100064 | C74: 45155 | D74: Temitope | E74: Olutola | F74: 500 | H74: =F74-I74 -> 500 | I74: =F74-(F74/(1+IF(G74="",$P$4,G74))) -> 0 | J74: Zelle | L74: Investment | S74: =IF(C74="","",MONTH(C74)) -> 8 | T74: =IF(C74="","",YEAR(C74)) -> 2023
B75: =B74+1 -> 100065 | C75: 45159 | D75: Abiodun | E75: Akindele | F75: 500 | H75: =F75-I75 -> 500 | I75: =F75-(F75/(1+IF(G75="",$P$4,G75))) -> 0 | J75: Zelle | L75: Investment | S75: =IF(C75="","",MONTH(C75)) -> 8 | T75: =IF(C75="","",YEAR(C75)) -> 2023
B76: =B75+1 -> 100066 | C76: 45160 | D76: Olumuyiwa | E76: Shoneye | F76: 550 | H76: =F76-I76 -> 550 | I76: =F76-(F76/(1+IF(G76="",$P$4,G76))) -> 0 | J76: Zelle | L76: Investment | S76: =IF(C76="","",MONTH(C76)) -> 8 | T76: =IF(C76="","",YEAR(C76)) -> 2023
B77: =B76+1 -> 100067 | C77: 45163 | D77: Temitope | E77: Ajibola | F77: 500 | H77: =F77-I77 -> 500 | I77: =F77-(F77/(1+IF(G77="",$P$4,G77))) -> 0 | J77: Zelle | L77: Investment | S77: =IF(C77="","",MONTH(C77)) -> 8 | T77: =IF(C77="","",YEAR(C77)) -> 2023
B78: =B77+1 -> 100068 | C78: 45167 | D78: Olurotimi | E78: Dosumu | F78: 500 | H78: =F78-I78 -> 500 | I78: =F78-(F78/(1+IF(G78="",$P$4,G78))) -> 0 | J78: Zelle | L78: Investment | S78: =IF(C78="","",MONTH(C78)) -> 8 | T78: =IF(C78="","",YEAR(C78)) -> 2023
B79: =B78+1 -> 100069 | C79: 45167 | D79: Olatunji | E79: Ilori | F79: 500 | H79: =F79-I79 -> 500 | I79: =F79-(F79/(1+IF(G79="",$P$4,G79))) -> 0 | J79: Zelle | L79: Investment | S79: =IF(C79="","",MONTH(C79)) -> 8 | T79: =IF(C79="","",YEAR(C79)) -> 2023
B80: =B79+1 -> 100070 | C80: 45170 | D80: Opeyemi | E80: Olomola | F80: 500 | H80: =F80-I80 -> 500 | I80: =F80-(F80/(1+IF(G80="",$P$4,G80))) -> 0 | J80: Zelle | L80: Investment | S80: =IF(C80="","",MONTH(C80)) -> 9 | T80: =IF(C80="","",YEAR(C80)) -> 2023
B81: =B80+1 -> 100071 | C81: 45174 | D81: Jamiu | E81: Momodu | F81: 500 | H81: =F81-I81 -> 500 | I81: =F81-(F81/(1+IF(G81="",$P$4,G81))) -> 0 | J81: Zelle | L81: Investment | S81: =IF(C81="","",MONTH(C81)) -> 9 | T81: =IF(C81="","",YEAR(C81)) -> 2023
B82: =B81+1 -> 100072 | C82: 45184 | D82: Temitope | E82: Ajibola | F82: 500 | H82: =F82-I82 -> 500 | I82: =F82-(F82/(1+IF(G82="",$P$4,G82))) -> 0 | J82: Zelle | L82: Investment | S82: =IF(C82="","",MONTH(C82)) -> 9 | T82: =IF(C82="","",YEAR(C82)) -> 2023
... B138: =B137+1 -> 100128 | C138: 45322 | D138: Olatunji | E138: Ilori | F138: 500 | H138: =F138-I138 -> 500 | I138: =F138-(F138/(1+IF(G138="",$P$4,G138))) -> 0 | J138: Zelle | L138: Investment | S138: =IF(C138="","",MONTH(C138)) -> 1 | T138: =IF(C138="","",YEAR(C138)) -> 2024
B139: =B138+1 -> 100129 | C139: 45322 | D139: Axios | E139: Interest | F139: 192.05 | H139: =F139-I139 -> 192.05 | I139: =F139-(F139/(1+IF(G139="",$P$4,G139))) -> 0 | J139: Bank Account | S139: =IF(C139="","",MONTH(C139)) -> 1 | T139: =IF(C139="","",YEAR(C139)) -> 2024
B140: =B139+1 -> 100130 | C140: 45327 | D140: Opeyemi | E140: Olomola | F140: 1000 | H140: =F140-I140 -> 1000 | I140: =F140-(F140/(1+IF(G140="",$P$4,G140))) -> 0 | J140: Zelle | L140: Investment | S140: =IF(C140="","",MONTH(C140)) -> 2 | T140: =IF(C140="","",YEAR(C140)) -> 2024
B141: =B140+1 -> 100131 | C141: 45329 | D141: Oluwafemi | E141: Durojaiye | F141: 600 | H141: =F141-I141 -> 600 | I141: =F141-(F141/(1+IF(G141="",$P$4,G141))) -> 0 | J141: Zelle | L141: Investment | S141: =IF(C141="","",MONTH(C141)) -> 2 | T141: =IF(C141="","",YEAR(C141)) -> 2024
B142: =B141+1 -> 100132 | C142: 45334 | D142: Temitope | E142: Olutola | F142: 1500 | H142: =F142-I142 -> 1500 | I142: =F142-(F142/(1+IF(G142="",$P$4,G142))) -> 0 | J142: Zelle | L142: Investment | S142: =IF(C142="","",MONTH(C142)) -> 2 | T142: =IF(C142="","",YEAR(C142)) -> 2024
B143: =B142+1 -> 100133 | C143: 45337 | D143: Dimeji | E143: Sule | F143: 500 | H143: =F143-I143 -> 500 | I143: =F143-(F143/(1+IF(G143="",$P$4,G143))) -> 0 | J143: Zelle | L143: Investment | S143: =IF(C143="","",MONTH(C143)) -> 2 | T143: =IF(C143="","",YEAR(C143)) -> 2024
...

Sheet Members
L1: SHARE PRICE CALCULATOR
EK2: Forecast
C3: 45017 | F3: 45047 | K3: 45078 | P3: 45108 | U3: 45139 | Z3: 45170 | AE3: 45200 | AJ3: 45231 | AO3: 45261 | AT3: 45292 | AY3: 45323 | BD3: 45352 | BI3: 45383 | BN3: 45413 | BS3: 45444 | BX3: 45474 | CC3: 45505 | CH3: 45536 | CM3: 45566 | CR3: 45597 | CW3: 45627 | DB3: 45658 | DG3: 45689 | DL3: 45717 | DQ3: 45748 | DV3: 45778 | EA3: 45809 | EF3: 45839 | EK3: 45870
B4: TerraCotta Share Price | C4: =C7/D9 -> 0.04 | F4: =F7/D9 -> 0.051315833 | K4: =K7/H9 -> 0.076028528 | P4: =P7/M9 -> 0.070970446 | U4: =U7/R9 -> 0.077428552 | Z4: =Z7/W9 -> 0.072332214 | AE4: =AE7/AB9 -> 0.079634193 | AJ4: =AJ7/AG9 -> 0.076319046 | AO4: =AO7/AL9 -> 0.070202145 | AT4: =AT7/AQ9 -> 0.080405622 | AY4: =AY7/AV9 -> 0.080067283 | BD4: =BD7/BA9 -> 0.088320591 | BI4: =BI7/BF9 -> 0.082628744 | BN4: =BN7/BK9 -> 0.079686492 | BS4: =BS7/BP9 -> 0.078849366 | BX4: =BX7/BU9 -> 0.079669817 | CC4: =CC7/BZ9 -> 0.073401159 | CH4: =CH7/CE9 -> 0.077482679 | CM4: =CM7/CJ9 -> 0.094147037 | CR4: =CR7/CO9 -> 0.079340885 | CW4: =CW7/CT9 -> 0.07571222 | DB4: =DB7/CY9 -> 0.071094219 | DG4: =DG7/DD9 -> 0.070311994 | DL4: =DL7/DI9 -> 0.069754763 | DQ4: =DQ7/CY9 -> 0.08536629 | DV4: =DV7/DD9 -> 0.083294964 | EA4: =EA7/DI9 -> 0.081375326 | EC4: BOA Balance | ED4: 7140.64 | EF4: =EF7/DN9 -> 0.077697034 | EH4: BOA Balance | EI4: 25589.16 | EK4: =EK7/DS9 -> 0.076065652
B5: Total Inflows | C5: =C9 -> 4800 | F5: =F9 -> 2200 | K5: =K9 -> 6225 | P5: =P9 -> 5000 | U5: =U9 -> 7050 | Z5: =Z9 -> 5000 | AE5: =AE9 -> 8500 | AJ5: =AJ9 -> 6600 | AO5: =AO9 -> 5192.76 | AT5: =AT9 -> 12692.05 | AY5: =AY9 -> 12325.41 | BD5: =BD9 -> 20776.84 | BI5: =BI9 -> 13244.6 | BN5: =BN9 -> 8800 | BS5: =BS9 -> 7737.18 | BX5: =BX9 -> 8472.49 | CC5: =CC9 -> 7280 | CH5: =CH9 -> 16297.89 | CM5: =CM9 -> 182651.57 | CR5: =CR9 -> -19541.57 | CW5: =CW9 -> 4873.05 | DB5: =DB9 -> 7600 | DG5: =DG9 -> 9352.64 | DL5: =DL9 -> 12690.84 | DQ5: =DQ9 -> 27075.63 | DV5: =DV9 -> 7450 | EA5: =EA9 -> 10460.36 | EC5: Axios Balance | ED5: 61411.26 | EF5: =EF9 -> 6194.85 | EH5: Axios Balance | EI5: 61606.11 | EK5: =EK9 -> 6500
B6: Total Outflows | C6: 0 | F6: 842.1 | K6: 0 | P6: 12.96 | U6: 14.4 | Z6: 20.4 | AE6: 28.8 | AJ6: 29.8 | AO6: 2682.49 | AT6: 28.8 | AY6: 128.8 | BD6: 28.8 | BI6: 29.8 | BN6: 28.8 | BS6: 232.8 | BX6: 28.8 | CC6: 10083.79 | CH6: 1513.63 | CM6: 137228.11 | CR6: 3516.99 | CW6: 3568.83 | DB6: 10643.36 | DG6: 3571.29 | DL6: 6319.94 | DQ6: 6488.78 | DV6: 3226.91 | EA6: 6077.23 | EC6: Wells Fargo Bal | ED6: 11551.75 | EF6: 3428.01 | EH6: Wells Fargo Bal | EI6: 464.75 | EK6: 3428.01
B7: TerraCotta Valuation | C7: 4800 | F7: =C7+(F5-F6) -> 6157.9 | K7: =F7+(K5-K6) -> 12382.9 | P7: =K7+(P5-P6) -> 17369.94 | U7: =P7+(U5-U6) -> 24405.54 | Z7: =U7+(Z5-Z6) -> 29385.14 | AE7: =Z7+(AE5-AE6) -> 37856.34 | AJ7: =AE7+(AJ5-AJ6) -> 44426.54 | AO7: =AJ7+(AO5-AO6) -> 46936.81 | AT7: =AO7+(AT5-AT6) -> 59600.06 | AY7: =AT7+(AY5-AY6) -> 71796.67 | BD7: =AY7+(BD5-BD6) -> 92544.71 | BI7: =BD7+(BI5-BI6) -> 105759.51 | BN7: =BI7+(BN5-BN6) -> 114530.71 | BS7: =BN7+(BS5-BS6) -> 122035.09 | BX7: =BS7+(BX5-BX6) -> 130478.78 | CC7: =BX7+(CC5-CC6) -> 127674.99 | CH7: =CC7+(CH5-CH6) -> 142459.25 | CM7: =CH7+(CM5-CM6) -> 187882.71 | CR7: =CM7+(CR5-CR6) -> 164824.15 | CW7: =CR7+(CW5-CW6) -> 166128.37 | DB7: =CW7+(DB5-DB6) -> 163085.01 | DG7: =DB7+(DG5-DG6) -> 168866.36 | DL7: =DG7+(DL5-DL6) -> 175237.26 | DQ7: =DL7+(DQ5-DQ6) -> 195824.11 | DV7: =DQ7+(DV5-DV6) -> 200047.2 | EA7: =DV7+(EA5-EA6) -> 204430.33 | EC7: Total Balance | ED7: =SUM(ED4:ED6) -> 80103.65 | EF7: =EA7+(EF5-EF6) -> 207197.17 | EH7: Total Balance | EI7: =SUM(EI4:EI6) -> 87660.02 | EK7: =EF7+(EK5-EK6) -> 210269.16
B9: Total | C9: =SUM(C12:C23) -> 4800 | D9: =SUM(D12:D23) -> 120000 | F9: =SUM(F12:F23) -> 2200 | G9: =SUM(G12:G23) -> 42871.758 | H9: =SUM(H12:H23) -> 162871.76 | K9: =SUM(K12:K23) -> 6225 | L9: =SUM(L12:L23) -> 81877.161 | M9: =SUM(M12:M23) -> 244748.92 | P9: =SUM(P12:P23) -> 5000 | Q9: =SUM(Q12:Q23) -> 70451.861 | R9: =SUM(R12:R23) -> 315200.78 | U9: =SUM(U12:U23) -> 7050 | V9: =SUM(V12:V23) -> 91051.683 | W9: =SUM(W12:W23) -> 406252.46 | Z9: =SUM(Z12:Z23) -> 5000 | AA9: =SUM(AA12:AA23) -> 69125.494 | AB9: =SUM(AB12:AB23) -> 475377.96 | AE9: =SUM(AE12:AE23) -> 8500 | AF9: =SUM(AF12:AF23) -> 106738.07 | AG9: =SUM(AG12:AG23) -> 582116.03 | AJ9: =SUM(AJ12:AJ23) -> 6600 | AK9: =SUM(AK12:AK23) -> 86479.068 | AL9: =SUM(AL12:AL23) -> 668595.09 | AO9: =SUM(AO12:AO26) -> 5192.76 | AP9: =SUM(AP12:AP26) -> 72647.352 | AQ9: =SUM(AQ12:AQ26) -> 741242.45 | AT9: =SUM(AT12:AT26) -> 12692.05 | AU9: =SUM(AU12:AU26) -> 155461.77 | AV9: =SUM(AV12:AV26) -> 896704.21 | AY9: =SUM(AY12:AY26) -> 12325.41 | AZ9: =SUM(AZ12:AZ26) -> 151122.9 | BA9: =SUM(BA12:BA26) -> 1047827.1 | BD9: =SUM(BD12:BD26) -> 20776.84 | BE9: =SUM(BE12:BE26) -> 232108.95 | BF9: =SUM(BF12:BF26) -> 1279936.1 | BI9: =SUM(BI12:BI26) -> 13244.6 | BJ9: =SUM(BJ12:BJ26) -> 157330.24 | BK9: =SUM(BK12:BK26) -> 1437266.3 | BN9: =SUM(BN12:BN26) -> 8800 | BO9: =SUM(BO12:BO26) -> 110432.77 | BP9: =SUM(BP12:BP26) -> 1547699.1 | BS9: =SUM(BS12:BS26) -> 7737.18 | BT9: =SUM(BT12:BT26) -> 90045.113 | BU9: =SUM(BU12:BU26) -> 1637744.2 | BX9: =SUM(BX12:BX26) -> 8472.49 | BY9: =SUM(BY12:BY26) -> 101669.62 | BZ9: =SUM(BZ12:BZ26) -> 1739413.8 | CC9: =SUM(CC12:CC26) -> 7280 | CD9: =SUM(CD12:CD26) -> 99180.995 | CE9: =SUM(CE12:CE26) -> 1838594.8 | CH9: =SUM(CH12:CH26) -> 16297.89 | CI9: =SUM(CI12:CI26) -> 157035.83 | CJ9: =SUM(CJ12:CJ24) -> 1995630.6 | CM9: =SUM(CM12:CM29) -> 182651.57 | CN9: =SUM(CN12:CN26) -> 81786.961 | CO9: =SUM(CO12:CO26) -> 2077417.6 | CR9: =SUM(CR12:CR26) +(sum(CR28:CR29) - sum(CM28:CM29)) -> -19541.57 | CS9: =SUM(CS12:CS26) -> 116790.57 | CT9: =SUM(CT12:CT26) -> 2194208.2 | CW9: =SUM(CW12:CW26) +(sum(CW28:CW29) - sum(CR28:CR29)) -> 4873.05 | CX9: =SUM(CX12:CX26) -> 99719.702 | CY9: =SUM(CY12:CY26) -> 2293927.9 | DB9: =SUM(DB12:DB26) +(sum(DB28:DB29) - sum(CW28:CW29)) -> 7600 | DC9: =SUM(DC12:DC26) -> 107744.34 | DD9: =SUM(DD12:DD26) -> 2401672.2 | DG9: =SUM(DG12:DG26) +(sum(DG28:DG29) - sum(DB28:DB29)) -> 9352.64 | DH9: =SUM(DH12:DH26) -> 110518.41 | DI9: =SUM(DI12:DI26) -> 2512190.6 | DL9: =SUM(DL12:DL27) +(sum(DL28:DL29) - sum(DG28:DG29)) -> 12690.84 | DM9: =SUM(DM12:DM26) -> 154541.42 | DN9: =SUM(DN12:DN26) -> 2666732 | DQ9: =SUM(DQ12:DQ27) +(sum(DQ28:DQ29) - sum(DL28:DL29)) -> 27075.63 | DR9: =SUM(DR12:DR26) -> 97579.501 | DS9: =SUM(DS12:DS26) -> 2764311.5 | DV9: =SUM(DV12:DV26) -> 7450 | DW9: =SUM(DW12:DW26) -> 90401.623 | DX9: =SUM(DX12:DX26) -> 2854713.2 | EA9: =SUM(EA12:EA26) -> 10460.36 | EB9: =SUM(EB12:EB26) -> 126942.66 | EC9: =SUM(EC12:EC26) -> 2981655.8 | EF9: =SUM(EF12:EF26) -> 6194.85 | EG9: =SUM(EG12:EG26) -> 77223.025 | EH9: =SUM(EH12:EH26) -> 3058878.8 | EK9: =SUM(EK12:EK26) -> 6500 | EL9: =SUM(EL12:EL26) -> 86109.825 | EM9: =SUM(EM12:EM26) -> 2850421.4
EO10: 2023 Total | EP10: 2024 Total | EQ10: 2024 Year end | ER10: 2025 Total | ES10: Overall Total
A11: ID | B11: MEMBER | C11: CONTR | D11: Shares | F11: CONTR | G11: Shares | H11: Total Shares | I11: % Shares | K11: CONTR | L11: Shares | M11: Total Shares | N11: % Shares | P11: CONTR | Q11: Shares | R11: Total Shares | S11: % Shares | U11: CONTR | V11: Shares | W11: Total Shares | X11: % Shares | Z11: CONTR | AA11: Shares | AB11: Total Shares | AC11: % shares | AE11: CONTR | AF11: Shares | AG11: Total Shares | AH11: % shares | AJ11: CONTR | AK11: Shares | AL11: Total Shares | AM11: % shares | AO11: CONTR | AP11: Shares | AQ11: Total Shares | AR11: % shares | AT11: CONTR | AU11: Shares | AV11: Total Shares | AW11: % shares | AY11: CONTR | AZ11: Shares | BA11: Total Shares | BB11: % shares | BD11: CONTR | BE11: Shares | BF11: Total Shares | BG11: % shares | BI11: CONTR | BJ11: Shares | BK11: Total Shares | BL11: % shares | BN11: CONTR | BO11: Shares | BP11: Total Shares | BQ11: % shares | BS11: CONTR | BT11: Shares | BU11: Total Shares | BV11: % shares | BX11: CONTR | BY11: Shares | BZ11: Total Shares | CA11: % shares | CC11: CONTR | CD11: Shares | CE11: Total Shares | CF11: % shares | CH11: CONTR | CI11: Shares | CJ11: Total Shares | CK11: % shares | CM11: CONTR | CN11: Shares | CO11: Total Shares | CP11: % shares | CR11: CONTR | CS11: Shares | CT11: Total Shares | CU11: % shares | CW11: CONTR | CX11: Shares | CY11: Total Shares | CZ11: % shares | DB11: CONTR | DC11: Shares | DD11: Total Shares | DE11: % shares | DG11: CONTR | DH11: Shares | DI11: Total Shares | DJ11: % shares | DL11: CONTR | DM11: Shares | DN11: Total Shares | DO11: % shares | DQ11: CONTR | DR11: Shares | DS11: Total Shares | DT11: % shares | DV11: CONTR | DW11: Shares | DX11: Total Shares | DY11: % shares | EA11: CONTR | EB11: Shares | EC11: Total Shares | ED11: % shares | EF11: CONTR | EG11: Shares | EH11: Total Shares | EI11: % shares | EK11: CONTR | EL11: Shares | EM11: Total Shares | EN11: % shares
A12: 1722 | B12: Ajala Oladapo | C12: 400 | D12: 10000 | F12: 200 | G12: =F12/F$4 -> 3897.4326 | H12: =D12+G12 -> 13897.433 | I12: =H12/$H$9 -> 0.085327455 | K12: 500 | L12: =K12/K$4 -> 6576.4788 | M12: =H12+L12 -> 20473.911 | N12: =M12/$M$9 -> 0.083652714 | P12: 500 | Q12: =P12/P$4 -> 7045.1861 | R12: =M12+Q12 -> 27519.097 | S12: =R12/$R$9 -> 0.087306565 | U12: 500 | V12: =U12/U$4 -> 6457.5662 | W12: =R12+V12 -> 33976.664 | X12: =W12/$W$9 -> 0.083634357 | Z12: 500 | AA12: =Z12/Z$4 -> 6912.5494 | AB12: =W12+AA12 -> 40889.213 | AC12: =AB12/$AB$9 -> 0.086014112 | AE12: 500 | AF12: =AE12/AE$4 -> 6278.7099 | AG12: =AB12+AF12 -> 47167.923 | AH12: =AG12/$AG$9 -> 0.081028388 | AJ12: 500 | AK12: =AJ12/AJ$4 -> 6551.4445 | AL12: =AG12+AK12 -> 53719.368 | AM12: =AL12/$AL$9 -> 0.080346637 | AO12: 500 | AP12: =AO12/AO$4 -> 7122.2895 | AQ12: =AL12+AP12 -> 60841.657 | AR12: =AQ12/$AQ$9 -> 0.082080643 | AT12: 500 | AU12: =AT12/AT$4 -> 6218.4706 | AV12: =AQ12+AU12 -> 67060.128 | AW12: =AV12/$AV$9 -> 0.074785115 | AY12: 500 | AZ12: =AY12/AY$4 -> 6244.7479 | BA12: =AV12+AZ12 -> 73304.876 | BB12: =BA12/$BA$9 -> 0.069958941 | BD12: 500 | BE12: =BD12/BD$4 -> 5661.194 | BF12: =BA12+BE12 -> 78966.07 | BG12: =BF12/$BF$9 -> 0.061695323 | BI12: 2500 | BJ12: =BI12/BI$4 -> 30255.815 | BK12: =BF12+BJ12 -> 109221.88 | BL12: =BK12/$BK$9 -> 0.075992796 | BN12: 2000 | BO12: =BN12/BN$4 -> 25098.357 | BP12: =BK12+BO12 -> 134320.24 | BQ12: =BP12/$BP$9 -> 0.086787053 | BS12: 1500 | BT12: =BS12/BS$4 -> 19023.615 | BU12: =BP12+BT12 -> 153343.86 | BV12: =BU12/$BU$9 -> 0.093631141 | BX12: 1000 | BY12: =BX12/BX$4 -> 12551.805 | BZ12: =BU12+BY12 -> 165895.66 | CA12: =BZ12/$BZ$9 -> 0.095374465 | CC12: 0 | CD12: =CC12/CC$4 -> 0 | CE12: =BZ12+CD12 -> 165895.66 | CF12: =CE12/$CE$9 -> 0.090229593 | CH12: 500 | CI12: =CH12/CH$4 -> 6453.0552 | CJ12: =CE12+CI12 -> 172348.72 | CK12: =CJ12/$CJ$9 -> 0.086363035 | CM12: 500 | CN12: =CM12/CM$4 -> 5310.8416 | CO12: =CJ12+CN12 -> 177659.56 | CP12: =CO12/$CO$9 -> 0.085519425 | CR12: 500 | CS12: =CR12/CR$4 -> 6301.9211 | CT12: =CO12+CS12 -> 183961.48 | CU12: =CT12/$CT$9 -> 0.083839575 | CW12: 500 | CX12: =CW12/CW$4 -> 6603.9538 | CY12: =CT12+CX12 -> 190565.43 | CZ12: =CY12/$CY$9 -> 0.083073856 | DB12: 500 | DC12: =DB12/DB$4 -> 7032.9206 | DD12: =CY12+DC12 -> 197598.35 | DE12: =DD12/$DD$9 -> 0.082275322 | DG12: 500 | DH12: =DG12/DG$4 -> 7111.1623 | DI12: =DD12+DH12 -> 204709.52 | DJ12: =DI12/$DI$9 -> 0.081486458 | DL12: 500 | DM12: =DL12/DL$4 -> 7167.9693 | DN12: =DI12+DM12 -> 211877.49 | DO12: =DN12/$DN$9 -> 0.079452109 | DQ12: 500 | DR12: =DQ12/DQ$4 -> 5857.1129 | DS12: =DN12+DR12 -> 217734.6 | DT12: =DS12/$DS$9 -> 0.078766302 | DV12: 0 | DW12: =DV12/DV$4 -> 0 | DX12: =DS12+DW12 -> 217734.6 | DY12: =DX12/$DX$9 -> 0.076271971 | EA12: 1000 | EB12: =EA12/EA$4 -> 12288.737 | EC12: =DX12+EB12 -> 230023.34 | ED12: =EC12/$EC$9 -> 0.077146173 | EF12: 500 | EG12: =EF12/EF$4 -> 6435.2521 | EH12: =EC12+EG12 -> 236458.59 | EI12: =EH12/$EH$9 -> 0.077302371 | EK12: 500 | EL12: =EK12/EK$4 -> 6573.2691 | EM12: =DS12+EL12 -> 224307.87 | EN12: =EM12/$EM$9 -> 0.078692881 | EO12: =C12+F12+K12+P12+U12+Z12+AE12+AJ12+AO12 -> 4100 | EP12: =AT12+AY12+BD12+BI12+BN12+BS12+BX12+CC12+CH12+CM12+CR12+CW12 -> 10500 | EQ12: =EO12+EP12 -> 14600 | ER12: =DB12+DG12+DL12+DQ12+DV12+EA12+EF12 -> 3500 | ES12: =EQ12+ER12 -> 18100
A13: =RANDBETWEEN(17,44) +A12 -> 1766 | B13: Ajibola Temitope | C13: 400 | D13: 10000 | F13: 200 | G13: =F13/F$4 -> 3897.4326 | H13: =D13+G13 -> 13897.433 | I13: =H13/$H$9 -> 0.085327455 | K13: 500 | L13: =K13/K$4 -> 6576.4788 | M13: =H13+L13 -> 20473.911 | N13: =M13/$M$9 -> 0.083652714 | P13: 500 | Q13: =P13/P$4 -> 7045.1861 | R13: =M13+Q13 -> 27519.097 | S13: =R13/$R$9 -> 0.087306565 | U13: 500 | V13: =U13/U$4 -> 6457.5662 | W13: =R13+V13 -> 33976.664 | X13: =W13/$W$9 -> 0.083634357 | Z13: 500 | AA13: =Z13/Z$4 -> 6912.5494 | AB13: =W13+AA13 -> 40889.213 | AC13: =AB13/$AB$9 -> 0.086014112 | AE13: 500 | AF13: =AE13/AE$4 -> 6278.7099 | AG13: =AB13+AF13 -> 47167.923 | AH13: =AG13/$AG$9 -> 0.081028388 | AJ13: 500 | AK13: =AJ13/AJ$4 -> 6551.4445 | AL13: =AG13+AK13 -> 53719.368 | AM13: =AL13/$AL$9 -> 0.080346637 | AO13: 1000 | AP13: =AO13/AO$4 -> 14244.579 | AQ13: =AL13+AP13 -> 67963.946 | AR13: =AQ13/$AQ$9 -> 0.091689226 | AT13: 1000 | AU13: =AT13/AT$4 -> 12436.941 | AV13: =AQ13+AU13 -> 80400.888 | AW13: =AV13/$AV$9 -> 0.089662663 | AY13: 1000 | AZ13: =AY13/AY$4 -> 12489.496 | BA13: =AV13+AZ13 -> 92890.384 | BB13: =BA13/$BA$9 -> 0.088650487 | BD13: 2500 | BE13: =BD13/BD$4 -> 28305.97 | BF13: =BA13+BE13 -> 121196.35 | BG13: =BF13/$BF$9 -> 0.094689381 | BI13: 500 | BJ13: =BI13/BI$4 -> 6051.163 | BK13: =BF13+BJ13 -> 127247.52 | BL13: =BK13/$BK$9 -> 0.088534405 | BN13: 500 | BO13: =BN13/BN$4 -> 6274.5892 | BP13: =BK13+BO13 -> 133522.11 | BQ13: =BP13/$BP$9 -> 0.086271361 | BS13: 600 | BT13: =BS13/BS$4 -> 7609.4461 | BU13: =BP13+BT13 -> 141131.55 | BV13: =BU13/$BU$9 -> 0.086174357 | BX13: 500 | BY13: =BX13/BX$4 -> 6275.9024 | BZ13: =BU13+BY13 -> 147407.45 | CA13: =BZ13/$BZ$9 -> 0.084745478 | CC13: 500 | CD13: =CC13/CC$4 -> 6811.8815 | CE13: =BZ13+CD13 -> 154219.34 | CF13: =CE13/$CE$9 -> 0.083878914 | CH13: 1000 | CI13: =CH13/CH$4 -> 12906.11 | CJ13: =CE13+CI13 -> 167125.45 | CK13: =CJ13/$CJ$9 -> 0.083745681 | CM13: 500 | CN13: =CM13/CM$4 -> 5310.8416 | CO13: =CJ13+CN13 -> 172436.29 | CP13: =CO13/$CO$9 -> 0.083005116 | CR13: 1000 | CS13: =CR13/CR$4 -> 12603.842 | CT13: =CO13+CS13 -> 185040.13 | CU13: =CT13/$CT$9 -> 0.084331165 | CW13: 600 | CX13: =CW13/CW$4 -> 7924.7445 | CY13: =CT13+CX13 -> 192964.87 | CZ13: =CY13/$CY$9 -> 0.084119853 | DB13: 600 | DC13: =DB13/DB$4 -> 8439.5047 | DD13: =CY13+DC13 -> 201404.38 | DE13: =DD13/$DD$9 -> 0.083860062 | DG13: 500 | DH13: =DG13/DG$4 -> 7111.1623 | DI13: =DD13+DH13 -> 208515.54 | DJ13: =DI13/$DI$9 -> 0.083001481 | DL13: 800 | DM13: =DL13/DL$4 -> 11468.751 | DN13: =DI13+DM13 -> 219984.29 | DO13: =DN13/$DN$9 -> 0.082492088 | DQ13: 800 | DR13: =DQ13/DQ$4 -> 9371.3807 | DS13: =DN13+DR13 -> 229355.67 | DT13: =DS13/$DS$9 -> 0.08297027 | DV13: 500 | DW13: =DV13/DV$4 -> 6002.7638 | DX13: =DS13+DW13 -> 235358.44 | DY13: =DX13/$DX$9 -> 0.082445564 | EA13: 500 | EB13: =EA13/EA$4 -> 6144.3686 | EC13: =DX13+EB13 -> 241502.81 | ED13: =EC13/$EC$9 -> 0.080996205 | EF13: 700 | EG13: =EF13/EF$4 -> 9009.3529 | EH13: =EC13+EG13 -> 250512.16 | EI13: =EH13/$EH$9 -> 0.081896725 | EK13: 500 | EL13: =EK13/EK$4 -> 6573.2691 | EM13: =DS13+EL13 -> 235928.94 | EN13: =EM13/$EM$9 -> 0.082769848 | EO13: =C13+F13+K13+P13+U13+Z13+AE13+AJ13+AO13 -> 4600 | EP13: =AT13+AY13+BD13+BI13+BN13+BS13+BX13+CC13+CH13+CM13+CR13+CW13 -> 10200 | EQ13: =EO13+EP13 -> 14800 | ER13: =DB13+DG13+DL13+DQ13+DV13+EA13+EF13 -> 4400 | ES13: =EQ13+ER13 -> 19200
